Workbook

Sheet Coefficients
A1: Standard Coefficients
E2: COEFFICIENT TABLE
F3: E 1% | G3: Estimated | K3: Limit of | L3: Limit of
A4: Calibration Date = | B4: 45945 | E4: Pigment | F4: λmax | G4: Coefficient | H4: Y intercept | I4: λmax | J4: Solvent | K4: Quantification (ng) | L4: Detection (ng) | M4: Notes
A5: Standard ID = | B5: DHI Standards
E6: β,β Carotene | F6: 2500 | G6: 0.0002353628 | H6: 0 | I6: 454 | J6: acetone
E7: β,ε Carotene | F7: 2700 | G7: 0.0002179224 | H7: 0 | I7: 448 | J7: acetone
E8: β,ψ Carotene | F8: 3185 | G8: 0.0001847408 | H8: 0 | I8: 459 | J8: pet ether
A9: E1% (1cm) = the extinction coefficient of a 1% solution in a 1 cm cuvette | E9: ε,ε Carotene | F9: 2900 | G9: 0.000202901 | H9: 0 | I9: 440 | J9: pet ether
E10: 19' but-Fuco | F10: 1470 | G10: 0.00013205026 | H10: 0 | I10: 445 | J10: acetone | K10: 0.53769487 | L10: 0.16130846
A11: [pigment] (mg/L) = abs/(E1% * 0.0001) | E11: 19' hex-Fuco | F11: 1420 | G11: 0.00014815254 | H11: 0 | I11: 445 | J11: acetone | K11: 0.4134224 | L11: 0.12402672
E12: Alloxanthin | F12: 2500 | G12: 7.7922244e-05 | H12: 0 | I12: 454 | J12: acetone | K12: 0.39327528 | L12: 0.11798258
A13: E1% values obtained from Mantoura & Llewellyn 1983 | E13: Antheraxanthin | F13: 2350 | G13: 0.00011915286 | H13: 0 | I13: 446 | J13: ethanol
B14: and Jeffrey et al. 1997 | E14: Aphanizophyll | G14: 0.00016859014 | H14: 0
E15: Astaxanthin | F15: 2100 | G15: 0.00010888096 | H15: 0 | I15: 468 | J15: hexane
E16: Bacteriochlorophyll a | F16: 594 | G16: 0.009439174 | H16: 0 | I16: 771 | J16: acetone/methanol | M16: Oelze 1985
A17: Red coefficients were determined from standards | E17: Canthaxanthin | F17: 2200 | G17: 0.00010393204 | H17: 0 | I17: 466 | J17: pet ether
A18: All others were estimated using LC 10AD coefficients | D18: 23 Sep 25 | E18: Chlorophyll a | F18: 876.7 | G18: 0.0004198 | H18: 0 | I18: 664.3 | J18: 90%acetone | K18: 1.3471794 | L18: 0.40415382
D19: Dec 21 | E19: Chlorophyll b | F19: 513.6 | G19: 0.00045591 | H19: 0 | I19: 646.8 | J19: 90%acetone | K19: 1.7053636 | L19: 0.51160907
E20: Chlorophyll c1c2 | F20: 426 | G20: 7.4207368e-05 | H20: 0 | I20: 630.7 | J20: 90%acetone | K20: Estimated | L20: Estimated | M20: Estimated
E21: Chlorophyll c3 | F21: 3460 | G21: 0.00014362252 | H21: 0 | I21: 452.9 | J21: 90%acetone | K21: 0.48770608 | L21: 0.14631182
E22: Chlorophyllide a | F22: 1270 | G22: 0.00018166454 | H22: 0 | I22: 664 | J22: 90%acetone
E23: Chlorophyllide b | F23: 740.7 | G23: 0.000296003 | H23: 0 | I23: 645 | J23: 90%acetone
E24: Crocoxanthin | F24: 2500 | G24: 8.120642e-05 | H24: 0 | I24: 443 | J24: ethanol
E25: Diadinochrome | F25: 2500 | G25: 7.650058e-05 | H25: 0 | I25: 428 | J25: acetone
E26: Diadinoxanthin | F26: 2250 | G26: 9.1103906e-05 | H26: 0 | I26: 444.5 | J26: methanol | K26: 0.37673066 | L26: 0.1130192
E27: Diatoxanthin | F27: 2100 | G27: 0.00012482394 | H27: 0 | I27: 452 | J27: acetone | K27: 0.4755478 | L27: 0.14266434
E28: Dinoxanthin | F28: 2100 | G28: 9.667386e-05 | H28: 0 | I28: 442 | J28: acetone
E29: Divinyl Chlorophyll a | F29: 876.7 | G29: 0.0004062622 | H29: 0 | I29: 664.3 | J29: 90%acetone | K29: 0.94742244 | L29: 0.28422673 | M29: Assume equal to Chla
E30: Divinyl Chlorophyll b | F30: 513.6 | G30: 0.0004268886 | H30: 0 | I30: 646.8 | J30: 90%acetone | M30: Assume equal to Chlb
E31: Echinenone | F31: 2158 | G31: 0.0002432098 | H31: 0 | I31: 458 | J31: pet ether
D32: Dec 21 | E32: Fucoxanthin | F32: 1660 | G32: 0.000120961 | H32: 0 | I32: 443 | J32: acetone | K32: 0.56341955 | L32: 0.16902586
E33: Gyroxanthin-diester | F33: 2620 | G33: 0.00017864846 | H33: 0 | I33: 445 | J33: ethanol | K33: 0.37706303 | L33: 0.11311891
E34: Lutein | F34: 2550 | G34: 0.00016679182 | H34: 0 | I34: 445 | J34: ethanol | K34: 0.36284085 | L34: 0.10885226
E35: Lycopene | F35: 3446 | G35: 0.0005660342 | H35: 0 | I35: 474 | J35: acetone
E36: Mg DVP | F36: 589 | G36: 0.0003722428 | H36: 0 | I36: 623 | J36: methanol
E37: Monadoxanthin | F37: 2500 | G37: 9.706798e-05 | H37: 0 | I37: 446 | J37: diethyl ether
E38: Myxoxanthophyll | F38: 2160 | G38: 0.00017631442 | H38: 0 | I38: 478 | J38: acetone | K38: 1.0390831 | L38: 0.31172492 | M38: Hirschberg & Chamovitz 1994
E39: Neoxanthin | F39: 2270 | G39: 0.00015527738 | H39: 0 | I39: 438 | J39: ethanol | K39: 0.31586075 | L39: 0.094758225
E40: P-457 | F40: 1640 | G40: 0.001189322 | H40: 0 | I40: 457 | J40: acetone
...

Sheet Internal Standard
A1: Internal Standard Calculation Sheet
C5: HPLC | D5: Acetone | E5: Carotenal | F5: Total Extract | G5: Volume of
C6: Injection | D6: Volume | E6: Volume | F6: Volume | G6: IP
C7: Volume | D7: Added | E7: Added | F7: added to Vial | G7: added to Vial
C8: (µL) | D8: (µL) | E8: (µL) | F8: (µL) | G8: (µL)
C10: 250 | D10: 750 | E10: 50 | F10: 500 | G10: 125
A13: Estimated Peak Area for Carotenal Standard Added | F13: =31527*(C10*(E10/(D10+E10))*(F10/(F10+G10))) -> 394087.5

Sheet Peak Areas
A2: Sample ID:
S4: PEAK AREAS
F6: Sample | G6: HPLC | H6: Acetone + Carotenal | I6: Extract | J6: Ammonium
F7: Filtered | G7: Injection | H7: Added | I7: Volume | J7: Acetate
E8: Special | F8: Volume | G8: Volume | H8: Volume | I8: in Vial | J8: Ratio
A9: Number | B9: Date | C9: Station | D9: Other | E9: Notes | F9: (Liters) | G9: (µL) | H9: (ml) | I9: (µL) | K9: Chl-ide a | L9: Chl c3 | M9: Chl c1c2 | N9: Perid | O9: 19'ButFuc | P9: Fuco | Q9: 19'HexFuc | R9: Neo | S9: Prasino | T9: Viola | U9: Diad | V9: Anther | W9: Allox | X9: Diat | Y9: Lutein | Z9: Zeax | AA9: Gyro | AB9: Carotenal | AC9: Chl b | AD9: Chla Allomer | AE9: Chl a | AF9: Chla prime | AG9: βε Carotene | AH9: ββ Carotene | AI9: Myxoxanthophyll | AJ9: Crocoxanthin
A10: Blank Line
A11: 1 | B11: 45809 | C11: control | F11: 0.1 | G11: 250 | H11: 0.8 | I11: 400 | J11: 1.25 | K11: 92030 | L11: 0 | M11: 155742 | N11: 11967 | O11: 0 | P11: 659149 | Q11: 4285 | R11: 159456 | S11: 0 | T11: 245619 | U11: 713555 | V11: 51550 | W11: 182650 | X11: 45035 | Y11: 319530 | Z11: 384517 | AA11: 36522 | AB11: 302433 | AC11: 186925 | AD11: 44990 | AE11: 1706500 | AF11: 36616 | AG11: 0 | AH11: 416293 | AI11: 34242 | AJ11: 13983
A12: 2 | B12: 45809 | C12: control | F12: 0.1 | G12: 250 | H12: 0.8 | I12: 400 | J12: 1.25 | K12: 62448 | L12: 0 | M12: 134223 | N12: 19049 | O12: 0 | P12: 652985 | Q12: 0 | R12: 163541 | S12: 0 | T12: 299991 | U12: 690212 | V12: 105248 | W12: 193217 | X12: 42277 | Y12: 317935 | Z12: 384473 | AA12: 35428 | AB12: 311790 | AC12: 189029 | AD12: 41263 | AE12: 1749729 | AF12: 40917 | AG12: 9317 | AH12: 410422 | AI12: 0 | AJ12: 13718
A13: 3 | B13: 45809 | C13: solvent | F13: 0.1 | G13: 250 | H13: 0.8 | I13: 400 | J13: 1.25 | K13: 51696 | L13: 0 | M13: 85770 | N13: 3702 | O13: 0 | P13: 443400 | Q13: 0 | R13: 147242 | S13: 0 | T13: 225387 | U13: 624782 | V13: 79843 | W13: 201631 | X13: 32197 | Y13: 351904 | Z13: 510445 | AA13: 32867 | AB13: 366166 | AC13: 173832 | AD13: 34767 | AE13: 1494339 | AF13: 39951 | AG13: 40669 | AH13: 428606 | AI13: 50653 | AJ13: 12720
A14: 4 | B14: 45809 | C14: solvent | F14: 0.1 | G14: 250 | H14: 0.8 | I14: 400 | J14: 1.25 | K14: 43556 | L14: 0 | M14: 78978 | N14: 10817 | O14: 0 | P14: 366462 | Q14: 0 | R14: 119987 | S14: 0 | T14: 185729 | U14: 540536 | V14: 65553 | W14: 177749 | X14: 28532 | Y14: 315208 | Z14: 471852 | AA14: 28807 | AB14: 329639 | AC14: 147330 | AD14: 29402 | AE14: 1264744 | AF14: 34318 | AG14: 36354 | AH14: 373079 | AI14: 42936 | AJ14: 9493
A15: 5 | B15: 45809 | C15: solvent nut | F15: 0.1 | G15: 250 | H15: 0.8 | I15: 400 | J15: 1.25 | K15: 48972 | L15: 0 | M15: 75703 | N15: 11680 | O15: 0 | P15: 301593 | Q15: 10780 | R15: 212933 | S15: 0 | T15: 244792 | U15: 500132 | V15: 61731 | W15: 218838 | X15: 29297 | Y15: 507787 | Z15: 470112 | AA15: 38505 | AB15: 370917 | AC15: 250911 | AD15: 42583 | AE15: 1720525 | AF15: 42458 | AG15: 71851 | AH15: 445168 | AI15: 40858 | AJ15: 16107
A16: 6 | B16: 45809 | C16: solvent nut | F16: 0.1 | G16: 250 | H16: 0.8 | I16: 400 | J16: 1.25 | K16: 59967 | L16: 0 | M16: 83780 | N16: 9211 | O16: 0 | P16: 297169 | Q16: 13039 | R16: 217726 | S16: 0 | T16: 251703 | U16: 514312 | V16: 63833 | W16: 230788 | X16: 30191 | Y16: 566274 | Z16: 488681 | AA16: 33177 | AB16: 359539 | AC16: 268890 | AD16: 46156 | AE16: 1763595 | AF16: 46375 | AG16: 76897 | AH16: 464402 | AI16: 39729 | AJ16: 16714
A17: 7 | B17: 45809 | C17: C low | F17: 0.1 | G17: 250 | H17: 0.8 | I17: 400 | J17: 1.25 | K17: 58558 | L17: 0 | M17: 148157 | N17: 13090 | O17: 0 | P17: 821666 | Q17: 0 | R17: 95810 | S17: 0 | T17: 304100 | U17: 677506 | V17: 59771 | W17: 206643 | X17: 36905 | Y17: 404694 | Z17: 385902 | AA17: 40492 | AB17: 349004 | AC17: 224649 | AD17: 43466 | AE17: 2089468 | AF17: 53310 | AG17: 11257 | AH17: 487275 | AI17: 46851 | AJ17: 16597
A18: 8 | B18: 45809 | C18: C low | F18: 0.1 | G18: 250 | H18: 0.8 | I18: 400 | J18: 1.25 | K18: 56641 | L18: 0 | M18: 154680 | N18: 13587 | O18: 0 | P18: 918788 | Q18: 0 | R18: 91346 | S18: 0 | T18: 304661 | U18: 733035 | V18: 47211 | W18: 207208 | X18: 38327 | Y18: 383358 | Z18: 407828 | AA18: 37264 | AB18: 370223 | AC18: 216246 | AD18: 39548 | AE18: 2207774 | AF18: 58138 | AG18: 12101 | AH18: 500329 | AI18: 50969 | AJ18: 15930
A19: 9 | B19: 45809 | C19: C high | F19: 0.1 | G19: 250 | H19: 0.8 | I19: 400 | J19: 1.25 | K19: 41095 | L19: 0 | M19: 102330 | N19: 14764 | O19: 0 | P19: 525576 | Q19: 0 | R19: 79853 | S19: 0 | T19: 229225 | U19: 594249 | V19: 79540 | W19: 193883 | X19: 29569 | Y19: 350030 | Z19: 498945 | AA19: 30862 | AB19: 366561 | AC19: 188246 | AD19: 46815 | AE19: 1677275 | AF19: 49862 | AG19: 9226 | AH19: 443596 | AI19: 19362 | AJ19: 17335
A20: 10 | B20: 45809 | C20: C high | F20: 0.1 | G20: 250 | H20: 0.8 | I20: 400 | J20: 1.25 | K20: 38123 | L20: 0 | M20: 94939 | N20: 12865 | O20: 0 | P20: 474316 | Q20: 0 | R20: 91852 | S20: 0 | T20: 225114 | U20: 576111 | V20: 74683 | W20: 192708 | X20: 29215 | Y20: 358562 | Z20: 541874 | AA20: 37170 | AB20: 369040 | AC20: 189892 | AD20: 43504 | AE20: 1682078 | AF20: 52211 | AG20: 44239 | AH20: 454212 | AI20: 20547 | AJ20: 15955
A21: 11 | B21: 45809 | C21: C low nut | F21: 0.1 | G21: 250 | H21: 0.8 | I21: 400 | J21: 1.25 | K21: 35021 | L21: 0 | M21: 132070 | N21: 9815 | O21: 0 | P21: 867068 | Q21: 0 | R21: 192198 | S21: 0 | T21: 294493 | U21: 687431 | V21: 63693 | W21: 199281 | X21: 28616 | Y21: 404318 | Z21: 412643 | AA21: 24096 | AB21: 384491 | AC21: 212122 | AD21: 34880 | AE21: 2156838 | AF21: 65453 | AG21: 9277 | AH21: 548228 | AI21: 59140 | AJ21: 15009
A22: 12 | B22: 45809 | C22: C low nut | F22: 0.1 | G22: 250 | H22: 0.8 | I22: 400 | J22: 1.25 | K22: 90278 | L22: 0 | M22: 180766 | N22: 13179 | O22: 0 | P22: 1000364 | Q22: 0 | R22: 219118 | S22: 0 | T22: 321767 | U22: 756236 | V22: 73617 | W22: 223675 | X22: 29206 | Y22: 436748 | Z22: 428496 | AA22: 50427 | AB22: 80854 | AC22: 238121 | AD22: 34680 | AE22: 2400117 | AF22: 73581 | AG22: 8899 | AH22: 595424 | AI22: 63086 | AJ22: 18289
... A198: 188 | B198: 45884 | C198: Q+D high nut | F198: 0.1 | G198: 250 | H198: 0.8 | I198: 400 | J198: 1.25 | K198: 29772 | L198: 0 | M198: 138230 | N198: 12493 | O198: 0 | P198: 274289 | Q198: 0 | R198: 73647 | S198: 0 | T198: 199228 | U198: 107449 | V198: 43181 | W198: 216113 | X198: 0 | Y198: 6883 | Z198: 188844 | AA198: 22295 | AB198: 404202 | AC198: 84081 | AD198: 13984 | AE198: 677099 | AF198: 80086 | AG198: 0 | AH198: 41823 | AI198: 43773 | AJ198: 14783

Sheet ug_liter
A1: HPLC PHOTOPIGMENT ANALYSIS FACILITY
A2: BARUCH INSTITUTE FOR MARINE AND COASTAL SCIENCES
A3: UNIVERSITY OF SOUTH CAROLINA | J3: Protocols and Methods Link
A4: COLUMBIA, SC 29208 USA | J4: Technical Description of Methods Link
A5: PINCKNEY@SC.EDU | C5: (803) 777.7133
B8: Sample ID: | C8: ='Peak Areas'!B2 -> 0
L9: PIGMENT CONCENTRATIONS
M10: (µg pigment liter-1)
M11: 0 Concentrations Indicate "Below Limits of Detection"
F12: Sample | G12: Volume | H12: Internal Std
A13: Number | B13: Date | C13: Station | D13: Other | E13: Notes | F13: Volume (L) | G13: Constants | H13: Constant | I13: Chl c3 | J13: Chl c1c2 | K13: Perid | L13: 19'ButFuc | M13: Fuco | N13: 19'HexFuc | O13: Neo | P13: Prasino | Q13: Viola | R13: Diad | S13: Anther | T13: Allox | U13: Diat | V13: Lutein | W13: Zeax | X13: Gyro | Y13: Chl b | Z13: Chla Allomer | AA13: Chl a | AB13: Chla prime | AC13: α Carotene | AD13: β Carotene | AF13: Chl-ide a | AG13: Total Chl a | AH13: ALL Chl a
A15: ='Peak Areas'!A11 -> 1 | B15: ='Peak Areas'!B11 -> 45809 | C15: ='Peak Areas'!C11 -> control | D15: ='Peak Areas'!D11 -> 0 | E15: ='Peak Areas'!E11 -> 0 | F15: ='Peak Areas'!F11 -> 0.1 | G15: =((1/'Peak Areas'!$G11)*(('Peak Areas'!$H11+('Internal Standard'!$E$10/1000))/'Peak Areas'!$F11)*'Peak Areas'!$J11)*H15 -> 0.055379931 | H15: =(('Internal Standard'!$F$13*('Peak Areas'!G11/'Internal Standard'!$C$10))/'Peak Areas'!AB11) -> 1.3030572 | I15: =IF('Peak Areas'!L11=0,0,((('Peak Areas'!L11*Coefficients!$G$21+Coefficients!$H$21)*$G15))) -> 0 | J15: =IF('Peak Areas'!M11=0,0,((('Peak Areas'!M11*Coefficients!$G$20+Coefficients!$H$20)*$G15))) -> 0.64003716 | K15: =IF('Peak Areas'!N11=0,0,((('Peak Areas'!N11*Coefficients!$G$41+Coefficients!$H$41)*$G15))) -> 0.11497334 | L15: =IF('Peak Areas'!O11=0,0,((('Peak Areas'!O11*Coefficients!$G$10+Coefficients!$H$10)*$G15))) -> 0 | M15: =IF('Peak Areas'!P11=0,0,((('Peak Areas'!P11*Coefficients!$G$32+Coefficients!$H$32)*$G15))) -> 4.4155151 | N15: =IF('Peak Areas'!Q11=0,0,((('Peak Areas'!Q11*Coefficients!$G$11+Coefficients!$H$11)*$G15))) -> 0.035157043 | O15: =IF('Peak Areas'!R11=0,0,((('Peak Areas'!R11*Coefficients!$G$39+Coefficients!$H$39)*$G15))) -> 1.3712021 | P15: =IF('Peak Areas'!S11=0,0,((('Peak Areas'!S11*Coefficients!$G$46+Coefficients!$H$46)*$G15))) -> 0 | Q15: =IF('Peak Areas'!T11=0,0,((('Peak Areas'!T11*Coefficients!$G$51+Coefficients!$H$51)*$G15))) -> 1.6422204 | R15: =IF('Peak Areas'!U11=0,0,((('Peak Areas'!U11*Coefficients!$G$26+Coefficients!$H$26)*$G15))) -> 3.6001191 | S15: =IF('Peak Areas'!V11=0,0,((('Peak Areas'!V11*Coefficients!$G$13+Coefficients!$H$13)*$G15))) -> 0.34016181 | T15: =IF('Peak Areas'!W11=0,0,((('Peak Areas'!W11*Coefficients!$G$12+Coefficients!$H$12)*$G15))) -> 0.78819475 | U15: =IF('Peak Areas'!X11=0,0,((('Peak Areas'!X11*Coefficients!$G$27+Coefficients!$H$27)*$G15))) -> 0.3113153 | V15: =IF('Peak Areas'!Y11=0,0,((('Peak Areas'!Y11*Coefficients!$G$34+Coefficients!$H$34)*$G15))) -> 2.9514729 | W15: =IF('Peak Areas'!Z11=0,0,((('Peak Areas'!Z11*Coefficients!$G$52+Coefficients!$H$52)*$G15))) -> 1.8229732 | X15: =IF('Peak Areas'!AA11=0,0,((('Peak Areas'!AA11*Coefficients!$G$33+Coefficients!$H$33)*$G15))) -> 0.36133185 | Y15: =IF('Peak Areas'!AC11=0,0,((('Peak Areas'!AC11*Coefficients!$G$19+Coefficients!$H$19)*$G15))) -> 4.7195318 | Z15: =IF('Peak Areas'!AD11=0,0,((('Peak Areas'!AD11*Coefficients!$G$18+Coefficients!$H$18)*$G15))) -> 1.0459498 | AA15: =IF('Peak Areas'!AE11=0,0,((('Peak Areas'!AE11*Coefficients!$G$18+Coefficients!$H$18)*$G15))) -> 39.673557 | AB15: =IF('Peak Areas'!AF11=0,0,((('Peak Areas'!AF11*Coefficients!$G$18+Coefficients!$H$18)*$G15))) -> 0.8512669 | AC15: =IF('Peak Areas'!AG11=0,0,((('Peak Areas'!AG11*Coefficients!$G$7+Coefficients!$H$7)*$G15))) -> 0 | AD15: =IF('Peak Areas'!AH11=0,0,((('Peak Areas'!AH11*Coefficients!$G$6+Coefficients!$H$6)*$G15))) -> 5.4261194 | AF15: =IF('Peak Areas'!K11=0,0,((('Peak Areas'!K11*Coefficients!$G$22+Coefficients!$H$22)*$G15))) -> 0.92587423 | AG15: =AA15+AF15 -> 40.599431 | AH15: =Z15+AA15+AB15+AF15 -> 42.496648
A16: ='Peak Areas'!A12 -> 2 | B16: ='Peak Areas'!B12 -> 45809 | C16: ='Peak Areas'!C12 -> control | D16: ='Peak Areas'!D12 -> 0 | E16: ='Peak Areas'!E12 -> 0 | F16: ='Peak Areas'!F12 -> 0.1 | G16: =((1/'Peak Areas'!$G12)*(('Peak Areas'!$H12+('Internal Standard'!$E$10/1000))/'Peak Areas'!$F12)*'Peak Areas'!$J12)*H16 -> 0.053717947 | H16: =(('Internal Standard'!$F$13*('Peak Areas'!G12/'Internal Standard'!$C$10))/'Peak Areas'!AB12) -> 1.2639517 | I16: =IF('Peak Areas'!L12=0,0,((('Peak Areas'!L12*Coefficients!$G$21+Coefficients!$H$21)*$G16))) -> 0 | J16: =IF('Peak Areas'!M12=0,0,((('Peak Areas'!M12*Coefficients!$G$20+Coefficients!$H$20)*$G16))) -> 0.53504878 | K16: =IF('Peak Areas'!N12=0,0,((('Peak Areas'!N12*Coefficients!$G$41+Coefficients!$H$41)*$G16))) -> 0.17752152 | L16: =IF('Peak Areas'!O12=0,0,((('Peak Areas'!O12*Coefficients!$G$10+Coefficients!$H$10)*$G16))) -> 0 | M16: =IF('Peak Areas'!P12=0,0,((('Peak Areas'!P12*Coefficients!$G$32+Coefficients!$H$32)*$G16))) -> 4.2429507 | N16: =IF('Peak Areas'!Q12=0,0,((('Peak Areas'!Q12*Coefficients!$G$11+Coefficients!$H$11)*$G16))) -> 0 | O16: =IF('Peak Areas'!R12=0,0,((('Peak Areas'!R12*Coefficients!$G$39+Coefficients!$H$39)*$G16))) -> 1.3641253 | P16: =IF('Peak Areas'!S12=0,0,((('Peak Areas'!S12*Coefficients!$G$46+Coefficients!$H$46)*$G16))) -> 0 | Q16: =IF('Peak Areas'!T12=0,0,((('Peak Areas'!T12*Coefficients!$G$51+Coefficients!$H$51)*$G16))) -> 1.9455603 | R16: =IF('Peak Areas'!U12=0,0,((('Peak Areas'!U12*Coefficients!$G$26+Coefficients!$H$26)*$G16))) -> 3.3778387 | S16: =IF('Peak Areas'!V12=0,0,((('Peak Areas'!V12*Coefficients!$G$13+Coefficients!$H$13)*$G16))) -> 0.6736553 | T16: =IF('Peak Areas'!W12=0,0,((('Peak Areas'!W12*Coefficients!$G$12+Coefficients!$H$12)*$G16))) -> 0.80877216 | U16: =IF('Peak Areas'!X12=0,0,((('Peak Areas'!X12*Coefficients!$G$27+Coefficients!$H$27)*$G16))) -> 0.28347937 | V16: =IF('Peak Areas'!Y12=0,0,((('Peak Areas'!Y12*Coefficients!$G$34+Coefficients!$H$34)*$G16))) -> 2.8486067 | W16: =IF('Peak Areas'!Z12=0,0,((('Peak Areas'!Z12*Coefficients!$G$52+Coefficients!$H$52)*$G16))) -> 1.7680623 | X16: =IF('Peak Areas'!AA12=0,0,((('Peak Areas'!AA12*Coefficients!$G$33+Coefficients!$H$33)*$G16))) -> 0.33998936 | Y16: =IF('Peak Areas'!AC12=0,0,((('Peak Areas'!AC12*Coefficients!$G$19+Coefficients!$H$19)*$G16))) -> 4.629424 | Z16: =IF('Peak Areas'!AD12=0,0,((('Peak Areas'!AD12*Coefficients!$G$18+Coefficients!$H$18)*$G16))) -> 0.93051342 | AA16: =IF('Peak Areas'!AE12=0,0,((('Peak Areas'!AE12*Coefficients!$G$18+Coefficients!$H$18)*$G16))) -> 39.457779 | AB16: =IF('Peak Areas'!AF12=0,0,((('Peak Areas'!AF12*Coefficients!$G$18+Coefficients!$H$18)*$G16))) -> 0.92271085 | AC16: =IF('Peak Areas'!AG12=0,0,((('Peak Areas'!AG12*Coefficients!$G$7+Coefficients!$H$7)*$G16))) -> 0.10906801 | AD16: =IF('Peak Areas'!AH12=0,0,((('Peak Areas'!AH12*Coefficients!$G$6+Coefficients!$H$6)*$G16))) -> 5.1890501 | AF16: =IF('Peak Areas'!K12=0,0,((('Peak Areas'!K12*Coefficients!$G$22+Coefficients!$H$22)*$G16))) -> 0.60940794 | AG16: =AA16+AF16 -> 40.067187 | AH16: =Z16+AA16+AB16+AF16 -> 41.920411
A17: ='Peak Areas'!A13 -> 3 | B17: ='Peak Areas'!B13 -> 45809 | C17: ='Peak Areas'!C13 -> solvent | D17: ='Peak Areas'!D13 -> 0 | E17: ='Peak Areas'!E13 -> 0 | F17: ='Peak Areas'!F13 -> 0.1 | G17: =((1/'Peak Areas'!$G13)*(('Peak Areas'!$H13+('Internal Standard'!$E$10/1000))/'Peak Areas'!$F13)*'Peak Areas'!$J13)*H17 -> 0.045740781 | H17: =(('Internal Standard'!$F$13*('Peak Areas'!G13/'Internal Standard'!$C$10))/'Peak Areas'!AB13) -> 1.0762537 | I17: =IF('Peak Areas'!L13=0,0,((('Peak Areas'!L13*Coefficients!$G$21+Coefficients!$H$21)*$G17))) -> 0 | J17: =IF('Peak Areas'!M13=0,0,((('Peak Areas'!M13*Coefficients!$G$20+Coefficients!$H$20)*$G17))) -> 0.29112936 | K17: =IF('Peak Areas'!N13=0,0,((('Peak Areas'!N13*Coefficients!$G$41+Coefficients!$H$41)*$G17))) -> 0.029376457 | L17: =IF('Peak Areas'!O13=0,0,((('Peak Areas'!O13*Coefficients!$G$10+Coefficients!$H$10)*$G17))) -> 0 | M17: =IF('Peak Areas'!P13=0,0,((('Peak Areas'!P13*Coefficients!$G$32+Coefficients!$H$32)*$G17))) -> 2.453266 | N17: =IF('Peak Areas'!Q13=0,0,((('Peak Areas'!Q13*Coefficients!$G$11+Coefficients!$H$11)*$G17))) -> 0 | O17: =IF('Peak Areas'!R13=0,0,((('Peak Areas'!R13*Coefficients!$G$39+Coefficients!$H$39)*$G17))) -> 1.0457876 | P17: =IF('Peak Areas'!S13=0,0,((('Peak Areas'!S13*Coefficients!$G$46+Coefficients!$H$46)*$G17))) -> 0 | Q17: =IF('Peak Areas'!T13=0,0,((('Peak Areas'!T13*Coefficients!$G$51+Coefficients!$H$51)*$G17))) -> 1.2446565 | R17: =IF('Peak Areas'!U13=0,0,((('Peak Areas'!U13*Coefficients!$G$26+Coefficients!$H$26)*$G17))) -> 2.6035689 | S17: =IF('Peak Areas'!V13=0,0,((('Peak Areas'!V13*Coefficients!$G$13+Coefficients!$H$13)*$G17))) -> 0.43515592 | T17: =IF('Peak Areas'!W13=0,0,((('Peak Areas'!W13*Coefficients!$G$12+Coefficients!$H$12)*$G17))) -> 0.71865811 | U17: =IF('Peak Areas'!X13=0,0,((('Peak Areas'!X13*Coefficients!$G$27+Coefficients!$H$27)*$G17))) -> 0.1838302 | V17: =IF('Peak Areas'!Y13=0,0,((('Peak Areas'!Y13*Coefficients!$G$34+Coefficients!$H$34)*$G17))) -> 2.6847418 | W17: =IF('Peak Areas'!Z13=0,0,((('Peak Areas'!Z13*Coefficients!$G$52+Coefficients!$H$52)*$G17))) -> 1.9987793 | X17: =IF('Peak Areas'!AA13=0,0,((('Peak Areas'!AA13*Coefficients!$G$33+Coefficients!$H$33)*$G17))) -> 0.26857335 | Y17: =IF('Peak Areas'!AC13=0,0,((('Peak Areas'!AC13*Coefficients!$G$19+Coefficients!$H$19)*$G17))) -> 3.6250368 | Z17: =IF('Peak Areas'!AD13=0,0,((('Peak Areas'!AD13*Coefficients!$G$18+Coefficients!$H$18)*$G17))) -> 0.66759523 | AA17: =IF('Peak Areas'!AE13=0,0,((('Peak Areas'!AE13*Coefficients!$G$18+Coefficients!$H$18)*$G17))) -> 28.694267 | AB17: =IF('Peak Areas'!AF13=0,0,((('Peak Areas'!AF13*Coefficients!$G$18+Coefficients!$H$18)*$G17))) -> 0.76713829 | AC17: =IF('Peak Areas'!AG13=0,0,((('Peak Areas'!AG13*Coefficients!$G$7+Coefficients!$H$7)*$G17))) -> 0.40538618 | AD17: =IF('Peak Areas'!AH13=0,0,((('Peak Areas'!AH13*Coefficients!$G$6+Coefficients!$H$6)*$G17))) -> 4.6142343 | AF17: =IF('Peak Areas'!K13=0,0,((('Peak Areas'!K13*Coefficients!$G$22+Coefficients!$H$22)*$G17))) -> 0.42956677 | AG17: =AA17+AF17 -> 29.123834 | AH17: =Z17+AA17+AB17+AF17 -> 30.558568
A18: ='Peak Areas'!A14 -> 4 | B18: ='Peak Areas'!B14 -> 45809 | C18: ='Peak Areas'!C14 -> solvent | D18: ='Peak Areas'!D14 -> 0 | E18: ='Peak Areas'!E14 -> 0 | F18: ='Peak Areas'!F14 -> 0.1 | G18: =((1/'Peak Areas'!$G14)*(('Peak Areas'!$H14+('Internal Standard'!$E$10/1000))/'Peak Areas'!$F14)*'Peak Areas'!$J14)*H18 -> 0.050809275 | H18: =(('Internal Standard'!$F$13*('Peak Areas'!G14/'Internal Standard'!$C$10))/'Peak Areas'!AB14) -> 1.1955124 | I18: =IF('Peak Areas'!L14=0,0,((('Peak Areas'!L14*Coefficients!$G$21+Coefficients!$H$21)*$G18))) -> 0 | J18: =IF('Peak Areas'!M14=0,0,((('Peak Areas'!M14*Coefficients!$G$20+Coefficients!$H$20)*$G18))) -> 0.29778044 | K18: =IF('Peak Areas'!N14=0,0,((('Peak Areas'!N14*Coefficients!$G$41+Coefficients!$H$41)*$G18))) -> 0.095347489 | L18: =IF('Peak Areas'!O14=0,0,((('Peak Areas'!O14*Coefficients!$G$10+Coefficients!$H$10)*$G18))) -> 0 | M18: =IF('Peak Areas'!P14=0,0,((('Peak Areas'!P14*Coefficients!$G$32+Coefficients!$H$32)*$G18))) -> 2.2522537 | N18: =IF('Peak Areas'!Q14=0,0,((('Peak Areas'!Q14*Coefficients!$G$11+Coefficients!$H$11)*$G18))) -> 0 | O18: =IF('Peak Areas'!R14=0,0,((('Peak Areas'!R14*Coefficients!$G$39+Coefficients!$H$39)*$G18))) -> 0.94664118 | P18: =IF('Peak Areas'!S14=0,0,((('Peak Areas'!S14*Coefficients!$G$46+Coefficients!$H$46)*$G18))) -> 0 | Q18: =IF('Peak Areas'!T14=0,0,((('Peak Areas'!T14*Coefficients!$G$51+Coefficients!$H$51)*$G18))) -> 1.1393044 | R18: =IF('Peak Areas'!U14=0,0,((('Peak Areas'!U14*Coefficients!$G$26+Coefficients!$H$26)*$G18))) -> 2.5020998 | S18: =IF('Peak Areas'!V14=0,0,((('Peak Areas'!V14*Coefficients!$G$13+Coefficients!$H$13)*$G18))) -> 0.39686248 | T18: =IF('Peak Areas'!W14=0,0,((('Peak Areas'!W14*Coefficients!$G$12+Coefficients!$H$12)*$G18))) -> 0.703739 | U18: =IF('Peak Areas'!X14=0,0,((('Peak Areas'!X14*Coefficients!$G$27+Coefficients!$H$27)*$G18))) -> 0.18095605 | V18: =IF('Peak Areas'!Y14=0,0,((('Peak Areas'!Y14*Coefficients!$G$34+Coefficients!$H$34)*$G18))) -> 2.6712527 | W18: =IF('Peak Areas'!Z14=0,0,((('Peak Areas'!Z14*Coefficients!$G$52+Coefficients!$H$52)*$G18))) -> 2.0523958 | X18: =IF('Peak Areas'!AA14=0,0,((('Peak Areas'!AA14*Coefficients!$G$33+Coefficients!$H$33)*$G18))) -> 0.2614811 | Y18: =IF('Peak Areas'!AC14=0,0,((('Peak Areas'!AC14*Coefficients!$G$19+Coefficients!$H$19)*$G18))) -> 3.4128194 | Z18: =IF('Peak Areas'!AD14=0,0,((('Peak Areas'!AD14*Coefficients!$G$18+Coefficients!$H$18)*$G18))) -> 0.62713683 | AA18: =IF('Peak Areas'!AE14=0,0,((('Peak Areas'!AE14*Coefficients!$G$18+Coefficients!$H$18)*$G18))) -> 26.976653 | AB18: =IF('Peak Areas'!AF14=0,0,((('Peak Areas'!AF14*Coefficients!$G$18+Coefficients!$H$18)*$G18))) -> 0.73199381 | AC18: =IF('Peak Areas'!AG14=0,0,((('Peak Areas'!AG14*Coefficients!$G$7+Coefficients!$H$7)*$G18))) -> 0.40252891 | AD18: =IF('Peak Areas'!AH14=0,0,((('Peak Areas'!AH14*Coefficients!$G$6+Coefficients!$H$6)*$G18))) -> 4.4615075 | AF18: =IF('Peak Areas'!K14=0,0,((('Peak Areas'!K14*Coefficients!$G$22+Coefficients!$H$22)*$G18))) -> 0.40203249 | AG18: =AA18+AF18 -> 27.378685 | AH18: =Z18+AA18+AB18+AF18 -> 28.737816
A19: ='Peak Areas'!A15 -> 5 | B19: ='Peak Areas'!B15 -> 45809 | C19: ='Peak Areas'!C15 -> solvent nut | D19: ='Peak Areas'!D15 -> 0 | E19: ='Peak Areas'!E15 -> 0 | F19: ='Peak Areas'!F15 -> 0.1 | G19: =((1/'Peak Areas'!$G15)*(('Peak Areas'!$H15+('Internal Standard'!$E$10/1000))/'Peak Areas'!$F15)*'Peak Areas'!$J15)*H19 -> 0.045154897 | H19: =(('Internal Standard'!$F$13*('Peak Areas'!G15/'Internal Standard'!$C$10))/'Peak Areas'!AB15) -> 1.0624682 | I19: =IF('Peak Areas'!L15=0,0,((('Peak Areas'!L15*Coefficients!$G$21+Coefficients!$H$21)*$G19))) -> 0 | J19: =IF('Peak Areas'!M15=0,0,((('Peak Areas'!M15*Coefficients!$G$20+Coefficients!$H$20)*$G19))) -> 0.25366758 | K19: =IF('Peak Areas'!N15=0,0,((('Peak Areas'!N15*Coefficients!$G$41+Coefficients!$H$41)*$G19))) -> 0.091497056 | L19: =IF('Peak Areas'!O15=0,0,((('Peak Areas'!O15*Coefficients!$G$10+Coefficients!$H$10)*$G19))) -> 0 | M19: =IF('Peak Areas'!P15=0,0,((('Peak Areas'!P15*Coefficients!$G$32+Coefficients!$H$32)*$G19))) -> 1.6472954 | N19: =IF('Peak Areas'!Q15=0,0,((('Peak Areas'!Q15*Coefficients!$G$11+Coefficients!$H$11)*$G19))) -> 0.07211618 | O19: =IF('Peak Areas'!R15=0,0,((('Peak Areas'!R15*Coefficients!$G$39+Coefficients!$H$39)*$G19))) -> 1.492987 | P19: =IF('Peak Areas'!S15=0,0,((('Peak Areas'!S15*Coefficients!$G$46+Coefficients!$H$46)*$G19))) -> 0 | Q19: =IF('Peak Areas'!T15=0,0,((('Peak Areas'!T15*Coefficients!$G$51+Coefficients!$H$51)*$G19))) -> 1.3345017 | R19: =IF('Peak Areas'!U15=0,0,((('Peak Areas'!U15*Coefficients!$G$26+Coefficients!$H$26)*$G19))) -> 2.0574367 | S19: =IF('Peak Areas'!V15=0,0,((('Peak Areas'!V15*Coefficients!$G$13+Coefficients!$H$13)*$G19))) -> 0.33213346 | T19: =IF('Peak Areas'!W15=0,0,((('Peak Areas'!W15*Coefficients!$G$12+Coefficients!$H$12)*$G19))) -> 0.76999701 | U19: =IF('Peak Areas'!X15=0,0,((('Peak Areas'!X15*Coefficients!$G$27+Coefficients!$H$27)*$G19))) -> 0.16512997 | V19: =IF('Peak Areas'!Y15=0,0,((('Peak Areas'!Y15*Coefficients!$G$34+Coefficients!$H$34)*$G19))) -> 3.8243812 | W19: =IF('Peak Areas'!Z15=0,0,((('Peak Areas'!Z15*Coefficients!$G$52+Coefficients!$H$52)*$G19))) -> 1.817266 | X19: =IF('Peak Areas'!AA15=0,0,((('Peak Areas'!AA15*Coefficients!$G$33+Coefficients!$H$33)*$G19))) -> 0.31061416 | Y19: =IF('Peak Areas'!AC15=0,0,((('Peak Areas'!AC15*Coefficients!$G$19+Coefficients!$H$19)*$G19))) -> 5.1653966 | Z19: =IF('Peak Areas'!AD15=0,0,((('Peak Areas'!AD15*Coefficients!$G$18+Coefficients!$H$18)*$G19))) -> 0.80720444 | AA19: =IF('Peak Areas'!AE15=0,0,((('Peak Areas'!AE15*Coefficients!$G$18+Coefficients!$H$18)*$G19))) -> 32.614316 | AB19: =IF('Peak Areas'!AF15=0,0,((('Peak Areas'!AF15*Coefficients!$G$18+Coefficients!$H$18)*$G19))) -> 0.80483493 | AC19: =IF('Peak Areas'!AG15=0,0,((('Peak Areas'!AG15*Coefficients!$G$7+Coefficients!$H$7)*$G19))) -> 0.70703277 | AD19: =IF('Peak Areas'!AH15=0,0,((('Peak Areas'!AH15*Coefficients!$G$6+Coefficients!$H$6)*$G19))) -> 4.7311488 | AF19: =IF('Peak Areas'!K15=0,0,((('Peak Areas'!K15*Coefficients!$G$22+Coefficients!$H$22)*$G19))) -> 0.40171945 | AG19: =AA19+AF19 -> 33.016035 | AH19: =Z19+AA19+AB19+AF19 -> 34.628075
A20: ='Peak Areas'!A16 -> 6 | B20: ='Peak Areas'!B16 -> 45809 | C20: ='Peak Areas'!C16 -> solvent nut | D20: ='Peak Areas'!D16 -> 0 | E20: ='Peak Areas'!E16 -> 0 | F20: ='Peak Areas'!F16 -> 0.1 | G20: =((1/'Peak Areas'!$G16)*(('Peak Areas'!$H16+('Internal Standard'!$E$10/1000))/'Peak Areas'!$F16)*'Peak Areas'!$J16)*H20 -> 0.046583872 | H20: =(('Internal Standard'!$F$13*('Peak Areas'!G16/'Internal Standard'!$C$10))/'Peak Areas'!AB16) -> 1.0960911 | I20: =IF('Peak Areas'!L16=0,0,((('Peak Areas'!L16*Coefficients!$G$21+Coefficients!$H$21)*$G20))) -> 0 | J20: =IF('Peak Areas'!M16=0,0,((('Peak Areas'!M16*Coefficients!$G$20+Coefficients!$H$20)*$G20))) -> 0.28961628 | K20: =IF('Peak Areas'!N16=0,0,((('Peak Areas'!N16*Coefficients!$G$41+Coefficients!$H$41)*$G20))) -> 0.074439216 | L20: =IF('Peak Areas'!O16=0,0,((('Peak Areas'!O16*Coefficients!$G$10+Coefficients!$H$10)*$G20))) -> 0 | M20: =IF('Peak Areas'!P16=0,0,((('Peak Areas'!P16*Coefficients!$G$32+Coefficients!$H$32)*$G20))) -> 1.6744973 | N20: =IF('Peak Areas'!Q16=0,0,((('Peak Areas'!Q16*Coefficients!$G$11+Coefficients!$H$11)*$G20))) -> 0.089988906 | O20: =IF('Peak Areas'!R16=0,0,((('Peak Areas'!R16*Coefficients!$G$39+Coefficients!$H$39)*$G20))) -> 1.5749039 | P20: =IF('Peak Areas'!S16=0,0,((('Peak Areas'!S16*Coefficients!$G$46+Coefficients!$H$46)*$G20))) -> 0 | Q20: =IF('Peak Areas'!T16=0,0,((('Peak Areas'!T16*Coefficients!$G$51+Coefficients!$H$51)*$G20))) -> 1.4156016 | R20: =IF('Peak Areas'!U16=0,0,((('Peak Areas'!U16*Coefficients!$G$26+Coefficients!$H$26)*$G20))) -> 2.1827261 | S20: =IF('Peak Areas'!V16=0,0,((('Peak Areas'!V16*Coefficients!$G$13+Coefficients!$H$13)*$G20))) -> 0.35431155 | T20: =IF('Peak Areas'!W16=0,0,((('Peak Areas'!W16*Coefficients!$G$12+Coefficients!$H$12)*$G20))) -> 0.83774194 | U20: =IF('Peak Areas'!X16=0,0,((('Peak Areas'!X16*Coefficients!$G$27+Coefficients!$H$27)*$G20))) -> 0.1755541 | V20: =IF('Peak Areas'!Y16=0,0,((('Peak Areas'!Y16*Coefficients!$G$34+Coefficients!$H$34)*$G20))) -> 4.3998407 | W20: =IF('Peak Areas'!Z16=0,0,((('Peak Areas'!Z16*Coefficients!$G$52+Coefficients!$H$52)*$G20))) -> 1.9488273 | X20: =IF('Peak Areas'!AA16=0,0,((('Peak Areas'!AA16*Coefficients!$G$33+Coefficients!$H$33)*$G20))) -> 0.27610354 | Y20: =IF('Peak Areas'!AC16=0,0,((('Peak Areas'!AC16*Coefficients!$G$19+Coefficients!$H$19)*$G20))) -> 5.7107001 | Z20: =IF('Peak Areas'!AD16=0,0,((('Peak Areas'!AD16*Coefficients!$G$18+Coefficients!$H$18)*$G20))) -> 0.90262256 | AA20: =IF('Peak Areas'!AE16=0,0,((('Peak Areas'!AE16*Coefficients!$G$18+Coefficients!$H$18)*$G20))) -> 34.488704 | AB20: =IF('Peak Areas'!AF16=0,0,((('Peak Areas'!AF16*Coefficients!$G$18+Coefficients!$H$18)*$G20))) -> 0.9069053 | AC20: =IF('Peak Areas'!AG16=0,0,((('Peak Areas'!AG16*Coefficients!$G$7+Coefficients!$H$7)*$G20))) -> 0.78063291 | AD20: =IF('Peak Areas'!AH16=0,0,((('Peak Areas'!AH16*Coefficients!$G$6+Coefficients!$H$6)*$G20))) -> 5.0917549 | AF20: =IF('Peak Areas'!K16=0,0,((('Peak Areas'!K16*Coefficients!$G$22+Coefficients!$H$22)*$G20))) -> 0.50747899 | AG20: =AA20+AF20 -> 34.996183 | AH20: =Z20+AA20+AB20+AF20 -> 36.805711
A21: ='Peak Areas'!A17 -> 7 | B21: ='Peak Areas'!B17 -> 45809 | C21: ='Peak Areas'!C17 -> C low | D21: ='Peak Areas'!D17 -> 0 | E21: ='Peak Areas'!E17 -> 0 | F21: ='Peak Areas'!F17 -> 0.1 | G21: =((1/'Peak Areas'!$G17)*(('Peak Areas'!$H17+('Internal Standard'!$E$10/1000))/'Peak Areas'!$F17)*'Peak Areas'!$J17)*H21 -> 0.047990048 | H21: =(('Internal Standard'!$F$13*('Peak Areas'!G17/'Internal Standard'!$C$10))/'Peak Areas'!AB17) -> 1.1291776 | I21: =IF('Peak Areas'!L17=0,0,((('Peak Areas'!L17*Coefficients!$G$21+Coefficients!$H$21)*$G21))) -> 0 | J21: =IF('Peak Areas'!M17=0,0,((('Peak Areas'!M17*Coefficients!$G$20+Coefficients!$H$20)*$G21))) -> 0.52761895 | K21: =IF('Peak Areas'!N17=0,0,((('Peak Areas'!N17*Coefficients!$G$41+Coefficients!$H$41)*$G21))) -> 0.10898087 | L21: =IF('Peak Areas'!O17=0,0,((('Peak Areas'!O17*Coefficients!$G$10+Coefficients!$H$10)*$G21))) -> 0 | M21: =IF('Peak Areas'!P17=0,0,((('Peak Areas'!P17*Coefficients!$G$32+Coefficients!$H$32)*$G21))) -> 4.7697089 | N21: =IF('Peak Areas'!Q17=0,0,((('Peak Areas'!Q17*Coefficients!$G$11+Coefficients!$H$11)*$G21))) -> 0 | O21: =IF('Peak Areas'!R17=0,0,((('Peak Areas'!R17*Coefficients!$G$39+Coefficients!$H$39)*$G21))) -> 0.71395398 | P21: =IF('Peak Areas'!S17=0,0,((('Peak Areas'!S17*Coefficients!$G$46+Coefficients!$H$46)*$G21))) -> 0 | Q21: =IF('Peak Areas'!T17=0,0,((('Peak Areas'!T17*Coefficients!$G$51+Coefficients!$H$51)*$G21))) -> 1.7619139 | R21: =IF('Peak Areas'!U17=0,0,((('Peak Areas'!U17*Coefficients!$G$26+Coefficients!$H$26)*$G21))) -> 2.962111 | S21: =IF('Peak Areas'!V17=0,0,((('Peak Areas'!V17*Coefficients!$G$13+Coefficients!$H$13)*$G21))) -> 0.34177963 | T21: =IF('Peak Areas'!W17=0,0,((('Peak Areas'!W17*Coefficients!$G$12+Coefficients!$H$12)*$G21))) -> 0.77273989 | U21: =IF('Peak Areas'!X17=0,0,((('Peak Areas'!X17*Coefficients!$G$27+Coefficients!$H$27)*$G21))) -> 0.22107228 | V21: =IF('Peak Areas'!Y17=0,0,((('Peak Areas'!Y17*Coefficients!$G$34+Coefficients!$H$34)*$G21))) -> 3.2393114 | W21: =IF('Peak Areas'!Z17=0,0,((('Peak Areas'!Z17*Coefficients!$G$52+Coefficients!$H$52)*$G21))) -> 1.5854061 | X21: =IF('Peak Areas'!AA17=0,0,((('Peak Areas'!AA17*Coefficients!$G$33+Coefficients!$H$33)*$G21))) -> 0.34715201 | Y21: =IF('Peak Areas'!AC17=0,0,((('Peak Areas'!AC17*Coefficients!$G$19+Coefficients!$H$19)*$G21))) -> 4.9151276 | Z21: =IF('Peak Areas'!AD17=0,0,((('Peak Areas'!AD17*Coefficients!$G$18+Coefficients!$H$18)*$G21))) -> 0.87567569 | AA21: =IF('Peak Areas'!AE17=0,0,((('Peak Areas'!AE17*Coefficients!$G$18+Coefficients!$H$18)*$G21))) -> 42.094887 | AB21: =IF('Peak Areas'!AF17=0,0,((('Peak Areas'!AF17*Coefficients!$G$18+Coefficients!$H$18)*$G21))) -> 1.0739951 | AC21: =IF('Peak Areas'!AG17=0,0,((('Peak Areas'!AG17*Coefficients!$G$7+Coefficients!$H$7)*$G21))) -> 0.1177269 | AD21: =IF('Peak Areas'!AH17=0,0,((('Peak Areas'!AH17*Coefficients!$G$6+Coefficients!$H$6)*$G21))) -> 5.5038063 | AF21: =IF('Peak Areas'!K17=0,0,((('Peak Areas'!K17*Coefficients!$G$22+Coefficients!$H$22)*$G21))) -> 0.51051392 | AG21: =AA21+AF21 -> 42.605401 | AH21: =Z21+AA21+AB21+AF21 -> 44.555071
A22: ='Peak Areas'!A18 -> 8 | B22: ='Peak Areas'!B18 -> 45809 | C22: ='Peak Areas'!C18 -> C low | D22: ='Peak Areas'!D18 -> 0 | E22: ='Peak Areas'!E18 -> 0 | F22: ='Peak Areas'!F18 -> 0.1 | G22: =((1/'Peak Areas'!$G18)*(('Peak Areas'!$H18+('Internal Standard'!$E$10/1000))/'Peak Areas'!$F18)*'Peak Areas'!$J18)*H22 -> 0.045239541 | H22: =(('Internal Standard'!$F$13*('Peak Areas'!G18/'Internal Standard'!$C$10))/'Peak Areas'!AB18) -> 1.0644598 | I22: =IF('Peak Areas'!L18=0,0,((('Peak Areas'!L18*Coefficients!$G$21+Coefficients!$H$21)*$G22))) -> 0 | J22: =IF('Peak Areas'!M18=0,0,((('Peak Areas'!M18*Coefficients!$G$20+Coefficients!$H$20)*$G22))) -> 0.51927736 | K22: =IF('Peak Areas'!N18=0,0,((('Peak Areas'!N18*Coefficients!$G$41+Coefficients!$H$41)*$G22))) -> 0.10663535 | L22: =IF('Peak Areas'!O18=0,0,((('Peak Areas'!O18*Coefficients!$G$10+Coefficients!$H$10)*$G22))) -> 0 | M22: =IF('Peak Areas'!P18=0,0,((('Peak Areas'!P18*Coefficients!$G$32+Coefficients!$H$32)*$G22))) -> 5.0278102 | N22: =IF('Peak Areas'!Q18=0,0,((('Peak Areas'!Q18*Coefficients!$G$11+Coefficients!$H$11)*$G22))) -> 0 | O22: =IF('Peak Areas'!R18=0,0,((('Peak Areas'!R18*Coefficients!$G$39+Coefficients!$H$39)*$G22))) -> 0.64167619 | P22: =IF('Peak Areas'!S18=0,0,((('Peak Areas'!S18*Coefficients!$G$46+Coefficients!$H$46)*$G22))) -> 0 | Q22: =IF('Peak Areas'!T18=0,0,((('Peak Areas'!T18*Coefficients!$G$51+Coefficients!$H$51)*$G22))) -> 1.6639954 | R22: =IF('Peak Areas'!U18=0,0,((('Peak Areas'!U18*Coefficients!$G$26+Coefficients!$H$26)*$G22))) -> 3.021203 | S22: =IF('Peak Areas'!V18=0,0,((('Peak Areas'!V18*Coefficients!$G$13+Coefficients!$H$13)*$G22))) -> 0.25448715 | T22: =IF('Peak Areas'!W18=0,0,((('Peak Areas'!W18*Coefficients!$G$12+Coefficients!$H$12)*$G22))) -> 0.73044272 | U22: =IF('Peak Areas'!X18=0,0,((('Peak Areas'!X18*Coefficients!$G$27+Coefficients!$H$27)*$G22))) -> 0.21643172 | V22: =IF('Peak Areas'!Y18=0,0,((('Peak Areas'!Y18*Coefficients!$G$34+Coefficients!$H$34)*$G22))) -> 2.8926605 | W22: =IF('Peak Areas'!Z18=0,0,((('Peak Areas'!Z18*Coefficients!$G$52+Coefficients!$H$52)*$G22))) -> 1.5794561 | X22: =IF('Peak Areas'!AA18=0,0,((('Peak Areas'!AA18*Coefficients!$G$33+Coefficients!$H$33)*$G22))) -> 0.30116669 | Y22: =IF('Peak Areas'!AC18=0,0,((('Peak Areas'!AC18*Coefficients!$G$19+Coefficients!$H$19)*$G22))) -> 4.4601082 | Z22: =IF('Peak Areas'!AD18=0,0,((('Peak Areas'!AD18*Coefficients!$G$18+Coefficients!$H$18)*$G22))) -> 0.75107819 | AA22: =IF('Peak Areas'!AE18=0,0,((('Peak Areas'!AE18*Coefficients!$G$18+Coefficients!$H$18)*$G22))) -> 41.929071 | AB22: =IF('Peak Areas'!AF18=0,0,((('Peak Areas'!AF18*Coefficients!$G$18+Coefficients!$H$18)*$G22))) -> 1.1041313 | AC22: =IF('Peak Areas'!AG18=0,0,((('Peak Areas'!AG18*Coefficients!$G$7+Coefficients!$H$7)*$G22))) -> 0.11930024 | AD22: =IF('Peak Areas'!AH18=0,0,((('Peak Areas'!AH18*Coefficients!$G$6+Coefficients!$H$6)*$G22))) -> 5.3273557 | AF22: =IF('Peak Areas'!K18=0,0,((('Peak Areas'!K18*Coefficients!$G$22+Coefficients!$H$22)*$G22))) -> 0.46549955 | AG22: =AA22+AF22 -> 42.394571 | AH22: =Z22+AA22+AB22+AF22 -> 44.24978
A23: ='Peak Areas'!A19 -> 9 | B23: ='Peak Areas'!B19 -> 45809 | C23: ='Peak Areas'!C19 -> C high | D23: ='Peak Areas'!D19 -> 0 | E23: ='Peak Areas'!E19 -> 0 | F23: ='Peak Areas'!F19 -> 0.1 | G23: =((1/'Peak Areas'!$G19)*(('Peak Areas'!$H19+('Internal Standard'!$E$10/1000))/'Peak Areas'!$F19)*'Peak Areas'!$J19)*H23 -> 0.045691491 | H23: =(('Internal Standard'!$F$13*('Peak Areas'!G19/'Internal Standard'!$C$10))/'Peak Areas'!AB19) -> 1.0750939 | I23: =IF('Peak Areas'!L19=0,0,((('Peak Areas'!L19*Coefficients!$G$21+Coefficients!$H$21)*$G23))) -> 0 | J23: =IF('Peak Areas'!M19=0,0,((('Peak Areas'!M19*Coefficients!$G$20+Coefficients!$H$20)*$G23))) -> 0.34696473 | K23: =IF('Peak Areas'!N19=0,0,((('Peak Areas'!N19*Coefficients!$G$41+Coefficients!$H$41)*$G23))) -> 0.11703043 | L23: =IF('Peak Areas'!O19=0,0,((('Peak Areas'!O19*Coefficients!$G$10+Coefficients!$H$10)*$G23))) -> 0 | M23: =IF('Peak Areas'!P19=0,0,((('Peak Areas'!P19*Coefficients!$G$32+Coefficients!$H$32)*$G23))) -> 2.9047999 | N23: =IF('Peak Areas'!Q19=0,0,((('Peak Areas'!Q19*Coefficients!$G$11+Coefficients!$H$11)*$G23))) -> 0 | O23: =IF('Peak Areas'!R19=0,0,((('Peak Areas'!R19*Coefficients!$G$39+Coefficients!$H$39)*$G23))) -> 0.56654546 | P23: =IF('Peak Areas'!S19=0,0,((('Peak Areas'!S19*Coefficients!$G$46+Coefficients!$H$46)*$G23))) -> 0 | Q23: =IF('Peak Areas'!T19=0,0,((('Peak Areas'!T19*Coefficients!$G$51+Coefficients!$H$51)*$G23))) -> 1.264487 | R23: =IF('Peak Areas'!U19=0,0,((('Peak Areas'!U19*Coefficients!$G$26+Coefficients!$H$26)*$G23))) -> 2.4736645 | S23: =IF('Peak Areas'!V19=0,0,((('Peak Areas'!V19*Coefficients!$G$13+Coefficients!$H$13)*$G23))) -> 0.43303738 | T23: =IF('Peak Areas'!W19=0,0,((('Peak Areas'!W19*Coefficients!$G$12+Coefficients!$H$12)*$G23))) -> 0.69029784 | U23: =IF('Peak Areas'!X19=0,0,((('Peak Areas'!X19*Coefficients!$G$27+Coefficients!$H$27)*$G23))) -> 0.1686436 | V23: =IF('Peak Areas'!Y19=0,0,((('Peak Areas'!Y19*Coefficients!$G$34+Coefficients!$H$34)*$G23))) -> 2.6675671 | W23: =IF('Peak Areas'!Z19=0,0,((('Peak Areas'!Z19*Coefficients!$G$52+Coefficients!$H$52)*$G23))) -> 1.9516428 | X23: =IF('Peak Areas'!AA19=0,0,((('Peak Areas'!AA19*Coefficients!$G$33+Coefficients!$H$33)*$G23))) -> 0.2519177 | Y23: =IF('Peak Areas'!AC19=0,0,((('Peak Areas'!AC19*Coefficients!$G$19+Coefficients!$H$19)*$G23))) -> 3.9213915 | Z23: =IF('Peak Areas'!AD19=0,0,((('Peak Areas'!AD19*Coefficients!$G$18+Coefficients!$H$18)*$G23))) -> 0.897972 | AA23: =IF('Peak Areas'!AE19=0,0,((('Peak Areas'!AE19*Coefficients!$G$18+Coefficients!$H$18)*$G23))) -> 32.172295 | AB23: =IF('Peak Areas'!AF19=0,0,((('Peak Areas'!AF19*Coefficients!$G$18+Coefficients!$H$18)*$G23))) -> 0.95641739 | AC23: =IF('Peak Areas'!AG19=0,0,((('Peak Areas'!AG19*Coefficients!$G$7+Coefficients!$H$7)*$G23))) -> 0.091865122 | AD23: =IF('Peak Areas'!AH19=0,0,((('Peak Areas'!AH19*Coefficients!$G$6+Coefficients!$H$6)*$G23))) -> 4.7704657 | AF23: =IF('Peak Areas'!K19=0,0,((('Peak Areas'!K19*Coefficients!$G$22+Coefficients!$H$22)*$G23))) -> 0.34111002 | AG23: =AA23+AF23 -> 32.513405 | AH23: =Z23+AA23+AB23+AF23 -> 34.367794
A24: ='Peak Areas'!A20 -> 10 | B24: ='Peak Areas'!B20 -> 45809 | C24: ='Peak Areas'!C20 -> C high | D24: ='Peak Areas'!D20 -> 0 | E24: ='Peak Areas'!E20 -> 0 | F24: ='Peak Areas'!F20 -> 0.1 | G24: =((1/'Peak Areas'!$G20)*(('Peak Areas'!$H20+('Internal Standard'!$E$10/1000))/'Peak Areas'!$F20)*'Peak Areas'!$J20)*H24 -> 0.045384562 | H24: =(('Internal Standard'!$F$13*('Peak Areas'!G20/'Internal Standard'!$C$10))/'Peak Areas'!AB20) -> 1.067872 | I24: =IF('Peak Areas'!L20=0,0,((('Peak Areas'!L20*Coefficients!$G$21+Coefficients!$H$21)*$G24))) -> 0 | J24: =IF('Peak Areas'!M20=0,0,((('Peak Areas'!M20*Coefficients!$G$20+Coefficients!$H$20)*$G24))) -> 0.3197421 | K24: =IF('Peak Areas'!N20=0,0,((('Peak Areas'!N20*Coefficients!$G$41+Coefficients!$H$41)*$G24))) -> 0.10129252 | L24: =IF('Peak Areas'!O20=0,0,((('Peak Areas'!O20*Coefficients!$G$10+Coefficients!$H$10)*$G24))) -> 0 | M24: =IF('Peak Areas'!P20=0,0,((('Peak Areas'!P20*Coefficients!$G$32+Coefficients!$H$32)*$G24))) -> 2.603882 | N24: =IF('Peak Areas'!Q20=0,0,((('Peak Areas'!Q20*Coefficients!$G$11+Coefficients!$H$11)*$G24))) -> 0 | O24: =IF('Peak Areas'!R20=0,0,((('Peak Areas'!R20*Coefficients!$G$39+Coefficients!$H$39)*$G24))) -> 0.64729904 | P24: =IF('Peak Areas'!S20=0,0,((('Peak Areas'!S20*Coefficients!$G$46+Coefficients!$H$46)*$G24))) -> 0 | Q24: =IF('Peak Areas'!T20=0,0,((('Peak Areas'!T20*Coefficients!$G$51+Coefficients!$H$51)*$G24))) -> 1.2334675 | R24: =IF('Peak Areas'!U20=0,0,((('Peak Areas'!U20*Coefficients!$G$26+Coefficients!$H$26)*$G24))) -> 2.3820524 | S24: =IF('Peak Areas'!V20=0,0,((('Peak Areas'!V20*Coefficients!$G$13+Coefficients!$H$13)*$G24))) -> 0.40386329 | T24: =IF('Peak Areas'!W20=0,0,((('Peak Areas'!W20*Coefficients!$G$12+Coefficients!$H$12)*$G24))) -> 0.68150547 | U24: =IF('Peak Areas'!X20=0,0,((('Peak Areas'!X20*Coefficients!$G$27+Coefficients!$H$27)*$G24))) -> 0.16550531 | V24: =IF('Peak Areas'!Y20=0,0,((('Peak Areas'!Y20*Coefficients!$G$34+Coefficients!$H$34)*$G24))) -> 2.7142332 | W24: =IF('Peak Areas'!Z20=0,0,((('Peak Areas'!Z20*Coefficients!$G$52+Coefficients!$H$52)*$G24))) -> 2.1053232 | X24: =IF('Peak Areas'!AA20=0,0,((('Peak Areas'!AA20*Coefficients!$G$33+Coefficients!$H$33)*$G24))) -> 0.30136998 | Y24: =IF('Peak Areas'!AC20=0,0,((('Peak Areas'!AC20*Coefficients!$G$19+Coefficients!$H$19)*$G24))) -> 3.9291077 | Z24: =IF('Peak Areas'!AD20=0,0,((('Peak Areas'!AD20*Coefficients!$G$18+Coefficients!$H$18)*$G24))) -> 0.82885731 | AA24: =IF('Peak Areas'!AE20=0,0,((('Peak Areas'!AE20*Coefficients!$G$18+Coefficients!$H$18)*$G24))) -> 32.047689 | AB24: =IF('Peak Areas'!AF20=0,0,((('Peak Areas'!AF20*Coefficients!$G$18+Coefficients!$H$18)*$G24))) -> 0.9947469 | AC24: =IF('Peak Areas'!AG20=0,0,((('Peak Areas'!AG20*Coefficients!$G$7+Coefficients!$H$7)*$G24))) -> 0.43753754 | AD24: =IF('Peak Areas'!AH20=0,0,((('Peak Areas'!AH20*Coefficients!$G$6+Coefficients!$H$6)*$G24))) -> 4.8518188 | AF24: =IF('Peak Areas'!K20=0,0,((('Peak Areas'!K20*Coefficients!$G$22+Coefficients!$H$22)*$G24))) -> 0.3143152 | AG24: =AA24+AF24 -> 32.362004 | AH24: =Z24+AA24+AB24+AF24 -> 34.185608
A25: ='Peak Areas'!A21 -> 11 | B25: ='Peak Areas'!B21 -> 45809 | C25: ='Peak Areas'!C21 -> C low nut | D25: ='Peak Areas'!D21 -> 0 | E25: ='Peak Areas'!E21 -> 0 | F25: ='Peak Areas'!F21 -> 0.1 | G25: =((1/'Peak Areas'!$G21)*(('Peak Areas'!$H21+('Internal Standard'!$E$10/1000))/'Peak Areas'!$F21)*'Peak Areas'!$J21)*H25 -> 0.043560756 | H25: =(('Internal Standard'!$F$13*('Peak Areas'!G21/'Internal Standard'!$C$10))/'Peak Areas'!AB21) -> 1.024959 | I25: =IF('Peak Areas'!L21=0,0,((('Peak Areas'!L21*Coefficients!$G$21+Coefficients!$H$21)*$G25))) -> 0 | J25: =IF('Peak Areas'!M21=0,0,((('Peak Areas'!M21*Coefficients!$G$20+Coefficients!$H$20)*$G25))) -> 0.42692011 | K25: =IF('Peak Areas'!N21=0,0,((('Peak Areas'!N21*Coefficients!$G$41+Coefficients!$H$41)*$G25))) -> 0.07417288 | L25: =IF('Peak Areas'!O21=0,0,((('Peak Areas'!O21*Coefficients!$G$10+Coefficients!$H$10)*$G25))) -> 0 | M25: =IF('Peak Areas'!P21=0,0,((('Peak Areas'!P21*Coefficients!$G$32+Coefficients!$H$32)*$G25))) -> 4.5687136 | N25: =IF('Peak Areas'!Q21=0,0,((('Peak Areas'!Q21*Coefficients!$G$11+Coefficients!$H$11)*$G25))) -> 0 | O25: =IF('Peak Areas'!R21=0,0,((('Peak Areas'!R21*Coefficients!$G$39+Coefficients!$H$39)*$G25))) -> 1.3000273 | P25: =IF('Peak Areas'!S21=0,0,((('Peak Areas'!S21*Coefficients!$G$46+Coefficients!$H$46)*$G25))) -> 0 | Q25: =IF('Peak Areas'!T21=0,0,((('Peak Areas'!T21*Coefficients!$G$51+Coefficients!$H$51)*$G25))) -> 1.5487719 | R25: =IF('Peak Areas'!U21=0,0,((('Peak Areas'!U21*Coefficients!$G$26+Coefficients!$H$26)*$G25))) -> 2.7281078 | S25: =IF('Peak Areas'!V21=0,0,((('Peak Areas'!V21*Coefficients!$G$13+Coefficients!$H$13)*$G25))) -> 0.33059143 | T25: =IF('Peak Areas'!W21=0,0,((('Peak Areas'!W21*Coefficients!$G$12+Coefficients!$H$12)*$G25))) -> 0.67642984 | U25: =IF('Peak Areas'!X21=0,0,((('Peak Areas'!X21*Coefficients!$G$27+Coefficients!$H$27)*$G25))) -> 0.15559736 | V25: =IF('Peak Areas'!Y21=0,0,((('Peak Areas'!Y21*Coefficients!$G$34+Coefficients!$H$34)*$G25))) -> 2.9376039 | W25: =IF('Peak Areas'!Z21=0,0,((('Peak Areas'!Z21*Coefficients!$G$52+Coefficients!$H$52)*$G25))) -> 1.5388001 | X25: =IF('Peak Areas'!AA21=0,0,((('Peak Areas'!AA21*Coefficients!$G$33+Coefficients!$H$33)*$G25))) -> 0.18751657 | Y25: =IF('Peak Areas'!AC21=0,0,((('Peak Areas'!AC21*Coefficients!$G$19+Coefficients!$H$19)*$G25))) -> 4.2126972 | Z25: =IF('Peak Areas'!AD21=0,0,((('Peak Areas'!AD21*Coefficients!$G$18+Coefficients!$H$18)*$G25))) -> 0.63784378 | AA25: =IF('Peak Areas'!AE21=0,0,((('Peak Areas'!AE21*Coefficients!$G$18+Coefficients!$H$18)*$G25))) -> 39.441677 | AB25: =IF('Peak Areas'!AF21=0,0,((('Peak Areas'!AF21*Coefficients!$G$18+Coefficients!$H$18)*$G25))) -> 1.1969263 | AC25: =IF('Peak Areas'!AG21=0,0,((('Peak Areas'!AG21*Coefficients!$G$7+Coefficients!$H$7)*$G25))) -> 0.088065305 | AD25: =IF('Peak Areas'!AH21=0,0,((('Peak Areas'!AH21*Coefficients!$G$6+Coefficients!$H$6)*$G25))) -> 5.6207523 | AF25: =IF('Peak Areas'!K21=0,0,((('Peak Areas'!K21*Coefficients!$G$22+Coefficients!$H$22)*$G25))) -> 0.27713675 | AG25: =AA25+AF25 -> 39.718814 | AH25: =Z25+AA25+AB25+AF25 -> 41.553584
A26: ='Peak Areas'!A22 -> 12 | B26: ='Peak Areas'!B22 -> 45809 | C26: ='Peak Areas'!C22 -> C low nut | D26: ='Peak Areas'!D22 -> 0 | E26: ='Peak Areas'!E22 -> 0 | F26: ='Peak Areas'!F22 -> 0.1 | G26: =((1/'Peak Areas'!$G22)*(('Peak Areas'!$H22+('Internal Standard'!$E$10/1000))/'Peak Areas'!$F22)*'Peak Areas'!$J22)*H26 -> 0.20714768 | H26: =(('Internal Standard'!$F$13*('Peak Areas'!G22/'Internal Standard'!$C$10))/'Peak Areas'!AB22) -> 4.8740631 | I26: =IF('Peak Areas'!L22=0,0,((('Peak Areas'!L22*Coefficients!$G$21+Coefficients!$H$21)*$G26))) -> 0 | J26: =IF('Peak Areas'!M22=0,0,((('Peak Areas'!M22*Coefficients!$G$20+Coefficients!$H$20)*$G26))) -> 2.778714 | K26: =IF('Peak Areas'!N22=0,0,((('Peak Areas'!N22*Coefficients!$G$41+Coefficients!$H$41)*$G26))) -> 0.4736112 | L26: =IF('Peak Areas'!O22=0,0,((('Peak Areas'!O22*Coefficients!$G$10+Coefficients!$H$10)*$G26))) -> 0 | M26: =IF('Peak Areas'!P22=0,0,((('Peak Areas'!P22*Coefficients!$G$32+Coefficients!$H$32)*$G26))) -> 25.065912 | N26: =IF('Peak Areas'!Q22=0,0,((('Peak Areas'!Q22*Coefficients!$G$11+Coefficients!$H$11)*$G26))) -> 0 | O26: =IF('Peak Areas'!R22=0,0,((('Peak Areas'!R22*Coefficients!$G$39+Coefficients!$H$39)*$G26))) -> 7.048007 | P26: =IF('Peak Areas'!S22=0,0,((('Peak Areas'!S22*Coefficients!$G$46+Coefficients!$H$46)*$G26))) -> 0 | Q26: =IF('Peak Areas'!T22=0,0,((('Peak Areas'!T22*Coefficients!$G$51+Coefficients!$H$51)*$G26))) -> 8.0470862 | R26: =IF('Peak Areas'!U22=0,0,((('Peak Areas'!U22*Coefficients!$G$26+Coefficients!$H$26)*$G26))) -> 14.271658 | S26: =IF('Peak Areas'!V22=0,0,((('Peak Areas'!V22*Coefficients!$G$13+Coefficients!$H$13)*$G26))) -> 1.8170324 | T26: =IF('Peak Areas'!W22=0,0,((('Peak Areas'!W22*Coefficients!$G$12+Coefficients!$H$12)*$G26))) -> 3.6104304 | U26: =IF('Peak Areas'!X22=0,0,((('Peak Areas'!X22*Coefficients!$G$27+Coefficients!$H$27)*$G26))) -> 0.75517925 | V26: =IF('Peak Areas'!Y22=0,0,((('Peak Areas'!Y22*Coefficients!$G$34+Coefficients!$H$34)*$G26))) -> 15.089879 | W26: =IF('Peak Areas'!Z22=0,0,((('Peak Areas'!Z22*Coefficients!$G$52+Coefficients!$H$52)*$G26))) -> 7.5986978 | X26: =IF('Peak Areas'!AA22=0,0,((('Peak Areas'!AA22*Coefficients!$G$33+Coefficients!$H$33)*$G26))) -> 1.8661326 | Y26: =IF('Peak Areas'!AC22=0,0,((('Peak Areas'!AC22*Coefficients!$G$19+Coefficients!$H$19)*$G26))) -> 22.488314 | Z26: =IF('Peak Areas'!AD22=0,0,((('Peak Areas'!AD22*Coefficients!$G$18+Coefficients!$H$18)*$G26))) -> 3.0157935 | AA26: =IF('Peak Areas'!AE22=0,0,((('Peak Areas'!AE22*Coefficients!$G$18+Coefficients!$H$18)*$G26))) -> 208.71561 | AB26: =IF('Peak Areas'!AF22=0,0,((('Peak Areas'!AF22*Coefficients!$G$18+Coefficients!$H$18)*$G26))) -> 6.3986477 | AC26: =IF('Peak Areas'!AG22=0,0,((('Peak Areas'!AG22*Coefficients!$G$7+Coefficients!$H$7)*$G26))) -> 0.40171973 | AD26: =IF('Peak Areas'!AH22=0,0,((('Peak Areas'!AH22*Coefficients!$G$6+Coefficients!$H$6)*$G26))) -> 29.029813 | AF26: =IF('Peak Areas'!K22=0,0,((('Peak Areas'!K22*Coefficients!$G$22+Coefficients!$H$22)*$G26))) -> 3.3972865 | AG26: =AA26+AF26 -> 212.11289 | AH26: =Z26+AA26+AB26+AF26 -> 221.52734
... A202: ='Peak Areas'!A198 -> 188 | B202: ='Peak Areas'!B198 -> 45884 | C202: ='Peak Areas'!C198 -> Q+D high nut | D202: ='Peak Areas'!D198 -> 0 | E202: ='Peak Areas'!E198 -> 0 | F202: ='Peak Areas'!F198 -> 0.1 | G202: =((1/'Peak Areas'!$G198)*(('Peak Areas'!$H198+('Internal Standard'!$E$10/1000))/'Peak Areas'!$F198)*'Peak Areas'!$J198)*H202 -> 0.041436506 | H202: =(('Internal Standard'!$F$13*('Peak Areas'!G198/'Internal Standard'!$C$10))/'Peak Areas'!AB198) -> 0.97497662 | I202: =IF('Peak Areas'!L198=0,0,((('Peak Areas'!L198*Coefficients!$G$21+Coefficients!$H$21)*$G202))) -> 0 | J202: =IF('Peak Areas'!M198=0,0,((('Peak Areas'!M198*Coefficients!$G$20+Coefficients!$H$20)*$G202))) -> 0.42504261 | K202: =IF('Peak Areas'!N198=0,0,((('Peak Areas'!N198*Coefficients!$G$41+Coefficients!$H$41)*$G202))) -> 0.089806816 | L202: =IF('Peak Areas'!O198=0,0,((('Peak Areas'!O198*Coefficients!$G$10+Coefficients!$H$10)*$G202))) -> 0 | M202: =IF('Peak Areas'!P198=0,0,((('Peak Areas'!P198*Coefficients!$G$32+Coefficients!$H$32)*$G202))) -> 1.3747917 | N202: =IF('Peak Areas'!Q198=0,0,((('Peak Areas'!Q198*Coefficients!$G$11+Coefficients!$H$11)*$G202))) -> 0 | O202: =IF('Peak Areas'!R198=0,0,((('Peak Areas'!R198*Coefficients!$G$39+Coefficients!$H$39)*$G202))) -> 0.473856 | P202: =IF('Peak Areas'!S198=0,0,((('Peak Areas'!S198*Coefficients!$G$46+Coefficients!$H$46)*$G202))) -> 0 | Q202: =IF('Peak Areas'!T198=0,0,((('Peak Areas'!T198*Coefficients!$G$51+Coefficients!$H$51)*$G202))) -> 0.99666815 | R202: =IF('Peak Areas'!U198=0,0,((('Peak Areas'!U198*Coefficients!$G$26+Coefficients!$H$26)*$G202))) -> 0.40562294 | S202: =IF('Peak Areas'!V198=0,0,((('Peak Areas'!V198*Coefficients!$G$13+Coefficients!$H$13)*$G202))) -> 0.21319661 | T202: =IF('Peak Areas'!W198=0,0,((('Peak Areas'!W198*Coefficients!$G$12+Coefficients!$H$12)*$G202))) -> 0.69779118 | U202: =IF('Peak Areas'!X198=0,0,((('Peak Areas'!X198*Coefficients!$G$27+Coefficients!$H$27)*$G202))) -> 0 | V202: =IF('Peak Areas'!Y198=0,0,((('Peak Areas'!Y198*Coefficients!$G$34+Coefficients!$H$34)*$G202))) -> 0.047570274 | W202: =IF('Peak Areas'!Z198=0,0,((('Peak Areas'!Z198*Coefficients!$G$52+Coefficients!$H$52)*$G202))) -> 0.66988252 | X202: =IF('Peak Areas'!AA198=0,0,((('Peak Areas'!AA198*Coefficients!$G$33+Coefficients!$H$33)*$G202))) -> 0.16504025 | Y202: =IF('Peak Areas'!AC198=0,0,((('Peak Areas'!AC198*Coefficients!$G$19+Coefficients!$H$19)*$G202))) -> 1.5884009 | Z202: =IF('Peak Areas'!AD198=0,0,((('Peak Areas'!AD198*Coefficients!$G$18+Coefficients!$H$18)*$G202))) -> 0.24325231 | AA202: =IF('Peak Areas'!AE198=0,0,((('Peak Areas'!AE198*Coefficients!$G$18+Coefficients!$H$18)*$G202))) -> 11.778168 | AB202: =IF('Peak Areas'!AF198=0,0,((('Peak Areas'!AF198*Coefficients!$G$18+Coefficients!$H$18)*$G202))) -> 1.3930996 | AC202: =IF('Peak Areas'!AG198=0,0,((('Peak Areas'!AG198*Coefficients!$G$7+Coefficients!$H$7)*$G202))) -> 0 | AD202: =IF('Peak Areas'!AH198=0,0,((('Peak Areas'!AH198*Coefficients!$G$6+Coefficients!$H$6)*$G202))) -> 0.4078835 | AF202: =IF('Peak Areas'!K198=0,0,((('Peak Areas'!K198*Coefficients!$G$22+Coefficients!$H$22)*$G202))) -> 0.22411004 | AG202: =AA202+AF202 -> 12.002278 | AH202: =Z202+AA202+AB202+AF202 -> 13.63863

Sheet Detection Limits
A1: Effective Limits of Detection and Quantification
D2: LODeff | E2: Effective Limit of Detection
D3: LOQeff | E3: Effective Limit of Quantification
M5: PIGMENT CONCENTRATIONS
N6: (µg pigment liter-1)
B7: Sample
B8: Number | D8: Chl c3 | G8: Perid | J8: 19'ButFuc | M8: Fuco | P8: 19'HexFuc | S8: Neo | V8: Viola | Y8: Diad | AB8: Allox | AE8: Diat | AH8: Lutein | AK8: Zeax | AN8: Gyro | AQ8: Chl b | AT8: Chl a
D9: LODeff | E9: LOQeff | G9: LODeff | H9: LOQeff | J9: LODeff | K9: LOQeff | M9: LODeff | N9: LOQeff | P9: LODeff | Q9: LOQeff | S9: LODeff | T9: LOQeff | V9: LODeff | W9: LOQeff | Y9: LODeff | Z9: LOQeff | AB9: LODeff | AC9: LOQeff | AE9: LODeff | AF9: LOQeff | AH9: LODeff | AI9: LOQeff | AK9: LODeff | AL9: LOQeff | AN9: LODeff | AO9: LOQeff | AQ9: LODeff | AR9: LOQeff | AT9: LODeff | AU9: LOQeff
B11: ='Peak Areas'!A11 -> 1 | D11: =((Coefficients!$L$21*('Peak Areas'!$H11+('Internal Standard'!$E$10/1000)))/(('Peak Areas'!$G11/1000)*'Peak Areas'!$F11))/1000 -> 0.004974602 | E11: =((Coefficients!$K$21*('Peak Areas'!$H11+('Internal Standard'!$E$10/1000)))/(('Peak Areas'!$G11/1000)*'Peak Areas'!$F11))/1000 -> 0.016582007 | G11: =((Coefficients!$L$41*('Peak Areas'!$H11+('Internal Standard'!$E$10/1000)))/(('Peak Areas'!$G11/1000)*'Peak Areas'!$F11))/1000 -> 0.005453868 | H11: =((Coefficients!$K$41*('Peak Areas'!$H11+('Internal Standard'!$E$10/1000)))/(('Peak Areas'!$G11/1000)*'Peak Areas'!$F11))/1000 -> 0.01817956 | J11: =((Coefficients!$L$10*('Peak Areas'!$H11+('Internal Standard'!$E$10/1000)))/(('Peak Areas'!$G11/1000)*'Peak Areas'!$F11))/1000 -> 0.0054844877 | K11: =((Coefficients!$K$10*('Peak Areas'!$H11+('Internal Standard'!$E$10/1000)))/(('Peak Areas'!$G11/1000)*'Peak Areas'!$F11))/1000 -> 0.018281626 | M11: =((Coefficients!$L$32*('Peak Areas'!$H11+('Internal Standard'!$E$10/1000)))/(('Peak Areas'!$G11/1000)*'Peak Areas'!$F11))/1000 -> 0.0057468794 | N11: =((Coefficients!$K$32*('Peak Areas'!$H11+('Internal Standard'!$E$10/1000)))/(('Peak Areas'!$G11/1000)*'Peak Areas'!$F11))/1000 -> 0.019156265 | P11: =((Coefficients!$L$11*('Peak Areas'!$H11+('Internal Standard'!$E$10/1000)))/(('Peak Areas'!$G11/1000)*'Peak Areas'!$F11))/1000 -> 0.0042169085 | Q11: =((Coefficients!$K$11*('Peak Areas'!$H11+('Internal Standard'!$E$10/1000)))/(('Peak Areas'!$G11/1000)*'Peak Areas'!$F11))/1000 -> 0.014056362 | S11: =((Coefficients!$L$39*('Peak Areas'!$H11+('Internal Standard'!$E$10/1000)))/(('Peak Areas'!$G11/1000)*'Peak Areas'!$F11))/1000 -> 0.0032217796 | T11: =((Coefficients!$K$39*('Peak Areas'!$H11+('Internal Standard'!$E$10/1000)))/(('Peak Areas'!$G11/1000)*'Peak Areas'!$F11))/1000 -> 0.010739265 | V11: =((Coefficients!$L$51*('Peak Areas'!$H11+('Internal Standard'!$E$10/1000)))/(('Peak Areas'!$G11/1000)*'Peak Areas'!$F11))/1000 -> 0.0044575654 | W11: =((Coefficients!$K$51*('Peak Areas'!$H11+('Internal Standard'!$E$10/1000)))/(('Peak Areas'!$G11/1000)*'Peak Areas'!$F11))/1000 -> 0.014858551 | Y11: =((Coefficients!$L$26*('Peak Areas'!$H11+('Internal Standard'!$E$10/1000)))/(('Peak Areas'!$G11/1000)*'Peak Areas'!$F11))/1000 -> 0.0038426528 | Z11: =((Coefficients!$K$26*('Peak Areas'!$H11+('Internal Standard'!$E$10/1000)))/(('Peak Areas'!$G11/1000)*'Peak Areas'!$F11))/1000 -> 0.012808843 | AB11: =((Coefficients!$L$12*('Peak Areas'!$H11+('Internal Standard'!$E$10/1000)))/(('Peak Areas'!$G11/1000)*'Peak Areas'!$F11))/1000 -> 0.0040114079 | AC11: =((Coefficients!$K$12*('Peak Areas'!$H11+('Internal Standard'!$E$10/1000)))/(('Peak Areas'!$G11/1000)*'Peak Areas'!$F11))/1000 -> 0.01337136 | AE11: =((Coefficients!$L$27*('Peak Areas'!$H11+('Internal Standard'!$E$10/1000)))/(('Peak Areas'!$G11/1000)*'Peak Areas'!$F11))/1000 -> 0.0048505875 | AF11: =((Coefficients!$K$27*('Peak Areas'!$H11+('Internal Standard'!$E$10/1000)))/(('Peak Areas'!$G11/1000)*'Peak Areas'!$F11))/1000 -> 0.016168625 | AH11: =((Coefficients!$L$34*('Peak Areas'!$H11+('Internal Standard'!$E$10/1000)))/(('Peak Areas'!$G11/1000)*'Peak Areas'!$F11))/1000 -> 0.0037009767 | AI11: =((Coefficients!$K$34*('Peak Areas'!$H11+('Internal Standard'!$E$10/1000)))/(('Peak Areas'!$G11/1000)*'Peak Areas'!$F11))/1000 -> 0.012336589 | AK11: =((Coefficients!$L$52*('Peak Areas'!$H11+('Internal Standard'!$E$10/1000)))/(('Peak Areas'!$G11/1000)*'Peak Areas'!$F11))/1000 -> 0.0048644575 | AL11: =((Coefficients!$K$52*('Peak Areas'!$H11+('Internal Standard'!$E$10/1000)))/(('Peak Areas'!$G11/1000)*'Peak Areas'!$F11))/1000 -> 0.016214858 | AN11: =((Coefficients!$L$33*('Peak Areas'!$H11+('Internal Standard'!$E$10/1000)))/(('Peak Areas'!$G11/1000)*'Peak Areas'!$F11))/1000 -> 0.0038460429 | AO11: =((Coefficients!$K$33*('Peak Areas'!$H11+('Internal Standard'!$E$10/1000)))/(('Peak Areas'!$G11/1000)*'Peak Areas'!$F11))/1000 -> 0.012820143 | AQ11: =((Coefficients!$L$19*('Peak Areas'!$H11+('Internal Standard'!$E$10/1000)))/(('Peak Areas'!$G11/1000)*'Peak Areas'!$F11))/1000 -> 0.017394708 | AR11: =((Coefficients!$K$19*('Peak Areas'!$H11+('Internal Standard'!$E$10/1000)))/(('Peak Areas'!$G11/1000)*'Peak Areas'!$F11))/1000 -> 0.057982361 | AT11: =((Coefficients!$L$18*('Peak Areas'!$H11+('Internal Standard'!$E$10/1000)))/(('Peak Areas'!$G11/1000)*'Peak Areas'!$F11))/1000 -> 0.01374123 | AU11: =((Coefficients!$K$18*('Peak Areas'!$H11+('Internal Standard'!$E$10/1000)))/(('Peak Areas'!$G11/1000)*'Peak Areas'!$F11))/1000 -> 0.0458041
